Workbook
Name climat: DATA!$B$5:$AV$5
Name Jeudis: DATA!$B$2:$AV$2
Name joueurs: DATA!$B$11:$AV$11
Name Jours: DATA!$B$1:$AV$2
Name mardi_jeudi: DATA!$B$3:$AV$3
Name Mardis: DATA!$B$1:$AV$1
Name match: DATA!$B$8:$AV$8
Name presence: DATA!$A$11:$AV$11
Name releve_meteo: DATA!$A$1:$AV$6
Name temp: DATA!$B$4:$AV$4
Name tot_jeudis: DATA!$B$14
Name tot_mardis: DATA!$B$13

Sheet Plan_Factoriel
A1: Présentation des data
A3: Valeur mesurée | B3: Presence moyenne : Présence des joueurs aux entrainements. Cette valeur est moyennée en fonctions des paramètres de tests de l'expériences
A5: Paramètres d'expériences
A6: Type de paramètre | B6: Paramètre | C6: Symbole | D6: Description, valeurs attendues
A7: Quantitatif | B7: Température | C7: T | D7: Température Extremum pendant la journée; valeur discrète simplifié à >10°C ou non
A8: Qualitatifs | B8: Jour | C8: D | D8: Jour d'entrainement; mardi ou jeudi
B9: Climat | C9: W | D9: beau temps ou pluie
B10: Match | C10: G | D10: Match le dimanche suivant l'entrainement oui ou non
A12: Plan Factiorel
A14: trial number | B14: D | C14: W | D14: T | E14: G | F14: Presence moyenne
A15: 1 | B15: mardi | C15: beau temps | D15: >10°C | E15: oui | F15: 32
A16: 2 | B16: mardi | C16: beau temps | D16: >10°C | E16: non | F16: 30.2
A17: 3 | B17: mardi | C17: beau temps | D17: <=10°C | E17: oui | F17: 32
A18: 4 | B18: mardi | C18: beau temps | D18: <=10°C | E18: non | F18: 29
A19: 5 | B19: mardi | C19: pluie | D19: >10°C | E19: oui | F19: 34
A20: 6 | B20: mardi | C20: pluie | D20: >10°C | E20: non | F20: 19
A21: 7 | B21: mardi | C21: pluie | D21: <=10°C | E21: oui | F21: 27
A22: 8 | B22: mardi | C22: pluie | D22: <=10°C | E22: non | F22: 17.5
A23: 9 | B23: jeudi | C23: beau temps | D23: >10°C | E23: oui | F23: 33.714286
A24: 10 | B24: jeudi | C24: beau temps | D24: >10°C | E24: non | F24: 29.25
A25: 11 | B25: jeudi | C25: beau temps | D25: <=10°C | E25: oui | F25: 32
A26: 12 | B26: jeudi | C26: beau temps | D26: <=10°C | E26: non | F26: 28
... A30: 16 | B30: jeudi | C30: pluie | D30: <=10°C | E30: non | F30: 29
A34: Codage du plan factiorel
A36: Paramètre | B36: valeur | C36: codage
A37: T | B37: >10°C | C37: 1
B38: <=10°C | C38: -1
A39: D | B39: mardi | C39: 1
B40: jeudi | C40: -1
A41: W | B41: beau temps | C41: 1
B42: pluie | C42: -1
A43: G | B43: oui | C43: 1
B44: non | C44: -1
A46: trial number | B46: D | C46: W | D46: T | E46: G | F46: Presence moyenne
A47: 1 | B47: 1 | C47: 1 | D47: 1 | E47: 1 | F47: =DATA!D17 -> 32
A48: 2 | B48: 1 | C48: 1 | D48: 1 | E48: -1 | F48: =DATA!D18 -> 30.2
A49: 3 | B49: 1 | C49: 1 | D49: -1 | E49: 1 | F49: =DATA!D19 -> 32
A50: 4 | B50: 1 | C50: 1 | D50: -1 | E50: -1 | F50: =DATA!D20 -> 29
A51: 5 | B51: 1 | C51: -1 | D51: 1 | E51: 1 | F51: =DATA!D21 -> 34
A52: 6 | B52: 1 | C52: -1 | D52: 1 | E52: -1 | F52: =DATA!D22 -> 19
...

Sheet DATA
A1: Mardis | B1: 45888 | D1: 45895 | F1: 45902 | G1: 45909 | I1: 45916 | K1: 45923 | M1: 45930 | O1: 45937 | Q1: 45944 | S1: 45951 | U1: 45958 | V1: 45965 | X1: 45972 | Z1: 45979 | AB1: 45986 | AD1: 45993 | AF1: 46000 | AH1: 46021 | AI1: 46028 | AK1: 46035 | AM1: 46042 | AO1: 46049 | AQ1: 46056 | AS1: 46063 | AU1: 46070
A2: Jeudis | C2: 45890 | E2: 45897 | H2: 45911 | J2: 45918 | L2: 45925 | N2: 45932 | P2: 45939 | R2: 45946 | T2: 45953 | W2: 45967 | Y2: 45974 | AA2: 45981 | AC2: 45988 | AE2: 45995 | AG2: 46002 | AJ2: 46030 | AL2: 46037 | AN2: 46044 | AP2: 46051 | AR2: 46058 | AT2: 46065 | AV2: 46072
A3: Mardi ou jeudi ? | B3: =IF(COUNTA(B1)>0,"mardi","jeudi") -> mardi | C3: =IF(COUNTA(C1)>0,"mardi","jeudi") -> jeudi | D3: =IF(COUNTA(D1)>0,"mardi","jeudi") -> mardi | E3: =IF(COUNTA(E1)>0,"mardi","jeudi") -> jeudi | F3: =IF(COUNTA(F1)>0,"mardi","jeudi") -> mardi | G3: =IF(COUNTA(G1)>0,"mardi","jeudi") -> mardi | H3: =IF(COUNTA(H1)>0,"mardi","jeudi") -> jeudi | I3: =IF(COUNTA(I1)>0,"mardi","jeudi") -> mardi | ... AV3: =IF(COUNTA(AV1)>0,"mardi","jeudi") -> jeudi
A4: Température | B4: 26 | C4: 22 | D4: 33 | E4: 24 | F4: 23 | G4: 22 | H4: 22 | I4: 19 | J4: 28 | K4: 8 | L4: 14 | M4: 14 | N4: 16 | O4: 18 | P4: 15 | Q4: 15 | R4: 15 | S4: 16 | T4: 16 | U4: 6 | V4: 17 | W4: 17 | X4: 15 | Y4: 18 | Z4: 4 | AA4: 5 | AB4: 6 | AC4: 5 | AD4: 7 | AE4: 8 | AF4: 14 | AG4: 12 | AH4: -3 | AI4: -8 | AJ4: 0 | AK4: 15 | AL4: 13 | AM4: 7 | AN4: 8 | AO4: 5 | AP4: 9 | AQ4: 9 | AR4: 11 | AS4: 11 | AT4: 10 | AU4: 9 | AV4: 9
A5: Climat, tendance générale du jour | B5: pluie | C5: beau | D5: beau | E5: pluie | F5: beau | G5: beau | H5: beau | I5: beau | J5: beau | K5: beau | L5: beau | M5: beau | N5: beau | O5: beau | P5: beau | Q5: beau | R5: beau | S5: pluie | T5: pluie | U5: beau | V5: beau | W5: beau | X5: beau | Y5: beau | Z5: beau | AA5: pluie | AB5: pluie | AC5: beau | AD5: beau | AE5: beau | AF5: beau | AG5: beau | AH5: pluie | AI5: beau | AJ5: pluie | AK5: beau | AL5: beau | AM5: beau | AN5: pluie | AO5: pluie | AP5: pluie | AQ5: pluie | AR5: pluie | AS5: pluie | AT5: pluie | AU5: pluie | AV5: pluie
A8: Match dimanche ? | B8: non | C8: non | D8: non | E8: non | F8: non | G8: non | H8: non | I8: oui | J8: oui | K8: oui | L8: oui | M8: oui | N8: oui | O8: non | P8: non | Q8: oui | R8: oui | S8: oui | T8: oui | U8: non | V8: oui | W8: oui | X8: oui | Y8: oui | Z8: oui | AA8: oui | AB8: non | AC8: non | AD8: oui | AE8: oui | AF8: oui | AG8: oui | AH8: non | AI8: non | AJ8: non | AK8: non | AL8: non | AM8: oui | AN8: oui | AO8: oui | AP8: oui | AQ8: oui | AR8: oui | AS8: non | AT8: non | AU8: oui | AV8: oui
A11: Presence joueurs | B11: 20 | C11: 23 | D11: 26 | E11: 31 | F11: 32 | G11: 32 | H11: 36 | I11: 38 | J11: 38 | K11: 31 | L11: 31 | M11: 33 | N11: 33 | O11: 29 | P11: 27 | Q11: 34 | R11: 37 | S11: 34 | T11: 39 | U11: 28 | V11: 31 | W11: 34 | X11: 30 | Y11: 35 | Z11: 32 | AA11: 33 | AB11: 21 | AC11: 28 | AD11: 34 | AE11: 32 | AF11: 26 | AG11: 28 | AH11: 14 | AI11: 30 | AJ11: 29 | AK11: 32 | AL11: 31 | AM11: 31 | AN11: 33 | AO11: 28 | AP11: 29 | AQ11: 31 | AR11: 30 | AS11: 18 | AT11: 29 | AU11: 22 | AV11: 28
A13: nombre de mardis | B13: =COUNTA(Mardis) -> 25
A14: nombre de jeudis | B14: =COUNTA(Jeudis) -> 22
A15: Calcul des moyennes de présences par paramètres
A16: trial number (situation) | B16: Total d'entrainements concernés | C16: Total de joueurs sur ces entrainements | D16: Moyenne de joueur/entrainement
A17: 1 | B17: =COUNTIFS(mardi_jeudi,"=mardi",climat,"=beau",temp,">10",match,"=oui") -> 6 | C17: =SUMIFS(joueurs,mardi_jeudi,"=mardi",climat,"=beau",temp,">10",match,"=oui") -> 192 | D17: =C17/B17 -> 32
A18: 2 | B18: =COUNTIFS(mardi_jeudi,"=mardi",climat,"=beau",temp,">10",match,"=non") -> 5 | C18: =SUMIFS(joueurs,mardi_jeudi,"=mardi",climat,"=beau",temp,">10",match,"=non") -> 151 | D18: =C18/B18 -> 30.2
A19: 3 | B19: =COUNTIFS(mardi_jeudi,"=mardi",climat,"=beau",temp,"<=10",match,"=oui") -> 4 | C19: =SUMIFS(joueurs,mardi_jeudi,"=mardi",climat,"=beau",temp,"<=10",match,"=oui") -> 128 | D19: =C19/B19 -> 32
A20: 4 | B20: =COUNTIFS(mardi_jeudi,"=mardi",climat,"=beau",temp,"<=10",match,"=non") -> 2 | C20: =SUMIFS(joueurs,mardi_jeudi,"=mardi",climat,"=beau",temp,"<=10",match,"=non") -> 58 | D20: =C20/B20 -> 29
A21: 5 | B21: =COUNTIFS(mardi_jeudi,"=mardi",climat,"=pluie",temp,">10",match,"=oui") -> 1 | C21: =SUMIFS(joueurs,mardi_jeudi,"=mardi",climat,"=pluie",temp,">10",match,"=oui") -> 34 | D21: =C21/B21 -> 34
A22: 6 | B22: =COUNTIFS(mardi_jeudi,"=mardi",climat,"=pluie",temp,">10",match,"=non") -> 2 | C22: =SUMIFS(joueurs,mardi_jeudi,"=mardi",climat,"=pluie",temp,">10",match,"=non") -> 38 | D22: =C22/B22 -> 19
A23: 7 | B23: =COUNTIFS(mardi_jeudi,"=mardi",climat,"=pluie",temp,"<=10",match,"=oui") -> 3 | C23: =SUMIFS(joueurs,mardi_jeudi,"=mardi",climat,"=pluie",temp,"<=10",match,"=oui") -> 81 | D23: =C23/B23 -> 27
A24: 8 | B24: =COUNTIFS(mardi_jeudi,"=mardi",climat,"=pluie",temp,"<=10",match,"=non") -> 2 | C24: =SUMIFS(joueurs,mardi_jeudi,"=mardi",climat,"=pluie",temp,"<=10",match,"=non") -> 35 | D24: =C24/B24 -> 17.5
A25: 9 | B25: =COUNTIFS(mardi_jeudi,"=jeudi",climat,"=beau",temp,">10",match,"=oui") -> 7 | C25: =SUMIFS(joueurs,mardi_jeudi,"=jeudi",climat,"=beau",temp,">10",match,"=oui") -> 236 | D25: =C25/B25 -> 33.714286
A26: 10 | B26: =COUNTIFS(mardi_jeudi,"=jeudi",climat,"=beau",temp,">10",match,"=non") -> 4 | C26: =SUMIFS(joueurs,mardi_jeudi,"=jeudi",climat,"=beau",temp,">10",match,"=non") -> 117 | D26: =C26/B26 -> 29.25
A27: 11 | B27: =COUNTIFS(mardi_jeudi,"=jeudi",climat,"=beau",temp,"<=10",match,"=oui") -> 1 | C27: =SUMIFS(joueurs,mardi_jeudi,"=jeudi",climat,"=beau",temp,"<=10",match,"=oui") -> 32 | D27: =C27/B27 -> 32
A28: 12 | B28: =COUNTIFS(mardi_jeudi,"=jeudi",climat,"=beau",temp,"<=10",match,"=non") -> 1 | C28: =SUMIFS(joueurs,mardi_jeudi,"=jeudi",climat,"=beau",temp,"<=10",match,"=non") -> 28 | D28: =C28/B28 -> 28
A29: 13 | B29: =COUNTIFS(mardi_jeudi,"=jeudi",climat,"=pluie",temp,">10",match,"=oui") -> 2 | C29: =SUMIFS(joueurs,mardi_jeudi,"=jeudi",climat,"=pluie",temp,">10",match,"=oui") -> 69 | D29: =C29/B29 -> 34.5
A30: 14 | B30: =COUNTIFS(mardi_jeudi,"=jeudi",climat,"=pluie",temp,">10",match,"=non") -> 1 | C30: =SUMIFS(joueurs,mardi_jeudi,"=jeudi",climat,"=pluie",temp,">10",match,"=non") -> 31 | D30: =C30/B30 -> 31
A31: 15 | B31: =COUNTIFS(mardi_jeudi,"=jeudi",climat,"=pluie",temp,"<=10",match,"=oui") -> 4 | C31: =SUMIFS(joueurs,mardi_jeudi,"=jeudi",climat,"=pluie",temp,"<=10",match,"=oui") -> 123 | D31: =C31/B31 -> 30.75
A32: 16 | B32: =COUNTIFS(mardi_jeudi,"=jeudi",climat,"=pluie",temp,"<=10",match,"=non") -> 2 | C32: =SUMIFS(joueurs,mardi_jeudi,"=jeudi",climat,"=pluie",temp,"<=10",match,"=non") -> 58 | D32: =C32/B32 -> 29

Sheet TO_ANALYSE
B2: trial number | C2: D | D2: W | E2: T | F2: G | G2: Presence moyenne
B3: 1 | C3: mardi | D3: beau temps | E3: >10°C | F3: oui | G3: 32
B4: 2 | C4: mardi | D4: beau temps | E4: >10°C | F4: non | G4: 30.2
B5: 3 | C5: mardi | D5: beau temps | E5: <=10°C | F5: oui | G5: 32
B6: 4 | C6: mardi | D6: beau temps | E6: <=10°C | F6: non | G6: 29
B7: 5 | C7: mardi | D7: pluie | E7: >10°C | F7: oui | G7: 34
B8: 6 | C8: mardi | D8: pluie | E8: >10°C | F8: non | G8: 19
B9: 7 | C9: mardi | D9: pluie | E9: <=10°C | F9: oui | G9: 27
B10: 8 | C10: mardi | D10: pluie | E10: <=10°C | F10: non | G10: 17.5
B11: 9 | C11: jeudi | D11: beau temps | E11: >10°C | F11: oui | G11: 33.714286
B12: 10 | C12: jeudi | D12: beau temps | E12: >10°C | F12: non | G12: 29.25
B13: 11 | C13: jeudi | D13: beau temps | E13: <=10°C | F13: oui | G13: 32
B14: 12 | C14: jeudi | D14: beau temps | E14: <=10°C | F14: non | G14: 28
... B18: 16 | C18: jeudi | D18: pluie | E18: <=10°C | F18: non | G18: 29
A20: Comparaison paramètre par paramètre
A22: Jour d'entrainement
B24: mardi | C24: jeudi
B25: 32 | C25: 33.714286
B26: 30.2 | C26: 29.25
B27: 32 | C27: 32
B28: 29 | C28: 28
B29: 34 | C29: 34.5
B30: 19 | C30: 31
B31: 27 | C31: 30.75
B32: 17.5 | C32: 29
A35: Climat
B37: beau temps | C37: pluie
B38: 32 | C38: 34
B39: 30.2 | C39: 19
B40: 32 | C40: 27
B41: 29 | C41: 17.5
B42: 33.714286 | C42: 34.5
B43: 29.25 | C43: 31
B44: 32 | C44: 30.75
B45: 28 | C45: 29
A48: Température
B50: >10°C | C50: <=10°C
B51: 32 | C51: 32
B52: 30.2 | C52: 29
B53: 34 | C53: 27
...

Sheet JOUR_ANALYSE
A1: Analyse de variance: un facteur
A3: RAPPORT DÉTAILLÉ JOUR DE LA SEMAINE
A4: Groupes | B4: Nombre d'échantillons | C4: Somme | D4: Moyenne | E4: Variance
A5: mardi | B5: 8 | C5: 220.7 | D5: 27.5875 | E5: 37.818393
A6: jeudi | B6: 8 | C6: 248.21429 | D6: 31.026786 | E6: 5.2480867
A9: ANALYSE DE VARIANCE
A10: Source des variations | B10: Somme des carrés | C10: Degré de liberté | D10: Moyenne des carrés | E10: F | F10: Probabilité | G10: Valeur critique pour F
A11: Entre Groupes | B11: 47.314745 | C11: 1 | D11: 47.314745 | E11: 2.1972887 | F11: 0.16041106 | G11: 4.6001099
A12: A l'intérieur des groupes | B12: 301.46536 | C12: 14 | D12: 21.53324
A14: Total | B14: 348.7801 | C14: 15

Sheet CLIMAT_ANALYSE
A1: Analyse de variance: un facteur
A3: RAPPORT DÉTAILLÉ CLIMAT
A4: Groupes | B4: Nombre d'échantillons | C4: Somme | D4: Moyenne | E4: Variance
A5: beau temps | B5: 8 | C5: 246.16429 | D5: 30.770536 | E5: 3.8069452
A6: pluie | B6: 8 | C6: 222.75 | D6: 27.84375 | E6: 41.123884
A9: ANALYSE DE VARIANCE
A10: Source des variations | B10: Somme des carrés | C10: Degré de liberté | D10: Moyenne des carrés | E10: F | F10: Probabilité | G10: Valeur critique pour F
A11: Entre Groupes | B11: 34.264298 | C11: 1 | D11: 34.264298 | E11: 1.5252021 | F11: 0.23715978 | G11: 4.6001099
A12: A l'intérieur des groupes | B12: 314.5158 | C12: 14 | D12: 22.465415
A14: Total | B14: 348.7801 | C14: 15

Sheet TEMPERATURE_ANALYSE
A1: Analyse de variance: un facteur
A3: RAPPORT DÉTAILLÉ TEMPERATURE
A4: Groupes | B4: Nombre d'échantillons | C4: Somme | D4: Moyenne | E4: Variance
A5: >10°C | B5: 8 | C5: 243.66429 | D5: 30.458036 | E5: 24.995721
A6: <=10°C | B6: 8 | C6: 225.25 | D6: 28.15625 | E6: 21.802455
A9: ANALYSE DE VARIANCE
A10: Source des variations | B10: Somme des carrés | C10: Degré de liberté | D10: Moyenne des carrés | E10: F | F10: Probabilité | G10: Valeur critique pour F
A11: Entre Groupes | B11: 21.19287 | C11: 1 | D11: 21.19287 | E11: 0.9057135 | F11: 0.35739672 | G11: 4.6001099
A12: A l'intérieur des groupes | B12: 327.58723 | C12: 14 | D12: 23.399088
A14: Total | B14: 348.7801 | C14: 15

Sheet MATCH_ANALYSE
A1: Analyse de variance: un facteur
A3: RAPPORT DÉTAILLÉ MATCH
A4: Groupes | B4: Nombre d'échantillons | C4: Somme | D4: Moyenne | E4: Variance
A5: oui | B5: 8 | C5: 255.96429 | D5: 31.995536 | E5: 5.6787309
A6: non | B6: 8 | C6: 212.95 | D6: 26.61875 | E6: 27.627098
A9: ANALYSE DE VARIANCE
A10: Source des variations | B10: Somme des carrés | C10: Degré de liberté | D10: Moyenne des carrés | E10: F | F10: Probabilité | G10: Valeur critique pour F
A11: Entre Groupes | B11: 115.6393 | C11: 1 | D11: 115.6393 | E11: 6.9440877 | F11: 0.01958817 | G11: 4.6001099
A12: A l'intérieur des groupes | B12: 233.1408 | C12: 14 | D12: 16.652915
A14: Total | B14: 348.7801 | C14: 15
